<sdf version='1.6'>
  <model name='mara'>
    <link name='table'>
      <pose frame=''>0 0 0.02 0 -0 0</pose>
      <inertial>
        <pose frame=''>-5e-06 -0 0.67145 0 -0 0</pose>
        <mass>14.066</mass>
        <inertia>
          <ixx>0.302278</ixx>
          <ixy>1.99824e-05</ixy>
          <ixz>3.12777e-11</ixz>
          <iyy>0.3023</iyy>
          <iyz>6.04033e-13</iyz>
          <izz>0.590436</izz>
        </inertia>
      </inertial>
      <collision name='table_collision'>
        <pose frame=''>0 0 0.6 0 -0 0</pose>
        <geometry>
          <box>
            <size>1.5 1 0.05</size>
          </box>
        </geometry>
      </collision>
      <collision name='table_fixed_joint_lump__base_link_collision_1'>
        <pose frame=''>0 0 0.62 0 0 -1.57</pose>
        <geometry>
          <mesh>
            <scale>0.001 0.001 0.001</scale>
            <uri>model://mara_description/meshes/Base_plancha.stl</uri>
          </mesh>
        </geometry>
        <surface>
          <contact>
            <ode/>
          </contact>
          <friction>
            <ode/>
          </friction>
        </surface>
      </collision>
      <collision name='table_fixed_joint_lump__base_robot_collision_2'>
        <pose frame=''>0 0 0.66 0 0 -1.57</pose>
        <geometry>
          <mesh>
            <scale>0.001 0.001 0.001</scale>
            <uri>model://mara_description/meshes/Base.stl</uri>
          </mesh>
        </geometry>
        <surface>
          <contact>
            <ode/>
          </contact>
          <friction>
            <ode/>
          </friction>
        </surface>
      </collision>
      <visual name='table_visual'>
        <pose frame=''>0 0 0.6 0 -0 0</pose>
        <geometry>
          <mesh>
            <scale>1.5 1 0.05</scale>
            <uri>model://mara_description/urdf/table.obj</uri>
          </mesh>
        </geometry>
      </visual>
      <visual name='table_visual_1'>
        <pose frame=''>-0.65 -0.4 0.29 0 -0 0</pose>
        <geometry>
          <mesh>
            <scale>0.1 0.1 0.58</scale>
            <uri>model://mara_description/urdf/table.obj</uri>
          </mesh>
        </geometry>
      </visual>
      <visual name='table_visual_2'>
        <pose frame=''>-0.65 0.4 0.29 0 -0 0</pose>
        <geometry>
          <mesh>
            <scale>0.1 0.1 0.58</scale>
            <uri>model://mara_description/urdf/table.obj</uri>
          </mesh>
        </geometry>
      </visual>
      <visual name='table_visual_3'>
        <pose frame=''>0.65 -0.4 0.29 0 -0 0</pose>
        <geometry>
          <mesh>
            <scale>0.1 0.1 0.58</scale>
            <uri>model://mara_description/urdf/table.obj</uri>
          </mesh>
        </geometry>
      </visual>
      <visual name='table_visual_4'>
        <pose frame=''>0.65 0.4 0.29 0 -0 0</pose>
        <geometry>
          <mesh>
            <scale>0.1 0.1 0.58</scale>
            <uri>model://mara_description/urdf/table.obj</uri>
          </mesh>
        </geometry>
      </visual>
      <visual name='table_fixed_joint_lump__base_link_visual_5'>
        <pose frame=''>0 0 0.62 0 0 -1.57</pose>
        <geometry>
          <mesh>
            <scale>0.001 0.001 0.001</scale>
            <uri>model://mara_description/meshes/Base_plancha.stl</uri>
          </mesh>
        </geometry>
        <material>
          <script>
            <name>Gazebo/Grey</name>
            <uri>file://media/materials/scripts/gazebo.material</uri>
          </script>
        </material>
      </visual>
      <visual name='table_fixed_joint_lump__base_robot_visual_6'>
        <pose frame=''>0 0 0.66 0 0 -1.57</pose>
        <geometry>
          <mesh>
            <scale>0.001 0.001 0.001</scale>
            <uri>model://mara_description/meshes/Base.stl</uri>
          </mesh>
        </geometry>
        <material>
          <script>
            <name>Gazebo/Grey</name>
            <uri>file://media/materials/scripts/gazebo.material</uri>
          </script>
        </material>
      </visual>
      <velocity_decay/>
      <gravity>1</gravity>
      <velocity_decay/>
      <self_collide>1</self_collide>
    </link>
    <joint name='world_to_table_joint' type='fixed'>
      <child>table</child>
      <parent>world</parent>
    </joint>
    <link name='motor1_link'>
      <pose frame=''>0 0 0.73122 0 0 -1.57</pose>
      <inertial>
        <pose frame=''>0 -5e-06 0.03145 0 -0 0</pose>
        <mass>11.6</mass>
        <inertia>
          <ixx>0.202118</ixx>
          <ixy>0.000422</ixy>
          <ixz>-0.008</ixz>
          <iyy>0.187732</iyy>
          <iyz>-0.0339707</iyz>
          <izz>0.0289987</izz>
        </inertia>
      </inertial>
      <collision name='motor1_link_collision'>
        <pose frame=''>0 0 0 0 -0 0</pose>
        <geometry>
          <mesh>
            <scale>0.001 0.001 0.001</scale>
            <uri>model://mara_description/meshes/MARA_T49.stl</uri>
          </mesh>
        </geometry>
        <surface>
          <contact>
            <ode/>
          </contact>
          <friction>
            <ode/>
          </friction>
        </surface>
      </collision>
      <collision name='motor1_link_fixed_joint_lump__motor1_cover_collision_1'>
        <pose frame=''>0 0 0 0 -0 0</pose>
        <geometry>
          <mesh>
            <scale>0.001 0.001 0.001</scale>
            <uri>model://mara_description/meshes/MARA_T49_Black.stl</uri>
          </mesh>
        </geometry>
        <surface>
          <contact>
            <ode/>
          </contact>
          <friction>
            <ode/>
          </friction>
        </surface>
      </collision>
      <visual name='motor1_link_visual'>
        <pose frame=''>0 0 0 0 -0 0</pose>
        <geometry>
          <mesh>
            <scale>0.001 0.001 0.001</scale>
            <uri>model://mara_description/meshes/MARA_T49.stl</uri>
          </mesh>
        </geometry>
        <material>
          <script>
            <name>Gazebo/White</name>
            <uri>file://media/materials/scripts/gazebo.material</uri>
          </script>
        </material>
      </visual>
      <visual name='motor1_link_fixed_joint_lump__motor1_cover_visual_1'>
        <pose frame=''>0 0 0 0 -0 0</pose>
        <geometry>
          <mesh>
            <scale>0.001 0.001 0.001</scale>
            <uri>model://mara_description/meshes/MARA_T49_Black.stl</uri>
          </mesh>
        </geometry>
        <material>
          <script>
            <name>Gazebo/Black</name>
            <uri>file://media/materials/scripts/gazebo.material</uri>
          </script>
        </material>
      </visual>
      <velocity_decay/>
      <gravity>1</gravity>
      <velocity_decay/>
      <self_collide>1</self_collide>
    </link>
    <joint name='motor1' type='revolute'>
      <child>motor1_link</child>
      <parent>table</parent>
      <axis>
        <xyz>0 0 -1</xyz>
        <limit>
          <lower>-2.3562</lower>
          <upper>2.3562</upper>
          <effort>330</effort>
          <velocity>3.1416</velocity>
        </limit>
        <dynamics>
          <damping>0</damping>
          <friction>0</friction>
          <spring_reference>0</spring_reference>
          <spring_stiffness>0</spring_stiffness>
        </dynamics>
        <use_parent_model_frame>1</use_parent_model_frame>
      </axis>
    </joint>
    <link name='motor2_link'>
      <pose frame=''>9.4e-05 -0.118 0.89492 0 0 -1.57</pose>
      <inertial>
        <pose frame=''>0 -5e-06 0.03145 0 -0 0</pose>
        <mass>1.03237</mass>
        <inertia>
          <ixx>0.0148652</ixx>
          <ixy>0</ixy>
          <ixz>0</ixz>
          <iyy>0.01557</iyy>
          <iyz>0.00071</iyz>
          <izz>0.00092</izz>
        </inertia>
      </inertial>
      <collision name='motor2_link_collision'>
        <pose frame=''>0 0 0 0 -0 0</pose>
        <geometry>
          <mesh>
            <scale>0.001 0.001 0.001</scale>
            <uri>model://mara_description/meshes/MARA_Link1.stl</uri>
          </mesh>
        </geometry>
        <surface>
          <contact>
            <ode/>
          </contact>
          <friction>
            <ode/>
          </friction>
        </surface>
      </collision>
      <visual name='motor2_link_visual'>
        <pose frame=''>0 0 0 0 -0 0</pose>
        <geometry>
          <mesh>
            <scale>0.001 0.001 0.001</scale>
            <uri>model://mara_description/meshes/MARA_Link1.stl</uri>
          </mesh>
        </geometry>
        <material>
          <script>
            <name>Gazebo/Black</name>
            <uri>file://media/materials/scripts/gazebo.material</uri>
          </script>
        </material>
      </visual>
      <gravity>1</gravity>
      <velocity_decay/>
      <self_collide>1</self_collide>
    </link>
    <joint name='motor2' type='revolute'>
      <child>motor2_link</child>
      <parent>motor1_link</parent>
      <axis>
        <xyz>0.000796 -1 0</xyz>
        <limit>
          <lower>-2.3562</lower>
          <upper>2.3562</upper>
          <effort>330</effort>
          <velocity>3.1416</velocity>
        </limit>
        <dynamics>
          <damping>0</damping>
          <friction>0</friction>
          <spring_reference>0</spring_reference>
          <spring_stiffness>0</spring_stiffness>
        </dynamics>
        <use_parent_model_frame>1</use_parent_model_frame>
      </axis>
    </joint>
    <link name='motor3_link'>
      <pose frame=''>8.7e-05 -0.109 1.09492 0 0 -1.57</pose>
      <inertial>
        <pose frame=''>0 -5e-06 0.03145 0 -0 0</pose>
        <mass>7.6</mass>
        <inertia>
          <ixx>0.09034</ixx>
          <ixy>4e-05</ixy>
          <ixz>-3.30872e-24</ixz>
          <iyy>0.03174</iyy>
          <iyz>0.02888</iyz>
          <izz>0.06606</izz>
        </inertia>
      </inertial>
      <collision name='motor3_link_collision'>
        <pose frame=''>0 0 0 0 -0 0</pose>
        <geometry>
          <mesh>
            <scale>0.001 0.001 0.001</scale>
            <uri>model://mara_description/meshes/MARA_T30.stl</uri>
          </mesh>
        </geometry>
        <surface>
          <contact>
            <ode/>
          </contact>
          <friction>
            <ode/>
          </friction>
        </surface>
      </collision>
      <collision name='motor3_link_fixed_joint_lump__motor3_cover_collision_1'>
        <pose frame=''>0 0 0 0 -0 0</pose>
        <geometry>
          <mesh>
            <scale>0.001 0.001 0.001</scale>
            <uri>model://mara_description/meshes/MARA_T30_Black.stl</uri>
          </mesh>
        </geometry>
        <surface>
          <contact>
            <ode/>
          </contact>
          <friction>
            <ode/>
          </friction>
        </surface>
      </collision>
      <visual name='motor3_link_visual'>
        <pose frame=''>0 0 0 0 -0 0</pose>
        <geometry>
          <mesh>
            <scale>0.001 0.001 0.001</scale>
            <uri>model://mara_description/meshes/MARA_T30.stl</uri>
          </mesh>
        </geometry>
        <material>
          <script>
            <name>Gazebo/White</name>
            <uri>file://media/materials/scripts/gazebo.material</uri>
          </script>
        </material>
      </visual>
      <visual name='motor3_link_fixed_joint_lump__motor3_cover_visual_1'>
        <pose frame=''>0 0 0 0 -0 0</pose>
        <geometry>
          <mesh>
            <scale>0.001 0.001 0.001</scale>
            <uri>model://mara_description/meshes/MARA_T30_Black.stl</uri>
          </mesh>
        </geometry>
        <material>
          <script>
            <name>Gazebo/Black</name>
            <uri>file://media/materials/scripts/gazebo.material</uri>
          </script>
        </material>
      </visual>
      <velocity_decay/>
      <gravity>1</gravity>
      <velocity_decay/>
      <self_collide>1</self_collide>
    </link>
    <joint name='motor3' type='revolute'>
      <child>motor3_link</child>
      <parent>motor2_link</parent>
      <axis>
        <xyz>0.000796 -1 0</xyz>
        <limit>
          <lower>-2.3562</lower>
          <upper>2.3562</upper>
          <effort>330</effort>
          <velocity>3.1416</velocity>
        </limit>
        <dynamics>
          <damping>0</damping>
          <friction>0</friction>
          <spring_reference>0</spring_reference>
          <spring_stiffness>0</spring_stiffness>
        </dynamics>
        <use_parent_model_frame>1</use_parent_model_frame>
      </axis>
    </joint>
    <link name='motor4_link'>
      <pose frame=''>-0 0.000255 1.24417 0 0 -1.57</pose>
      <inertial>
        <pose frame=''>0 -5e-06 0.03145 0 -0 0</pose>
        <mass>1.1</mass>
        <inertia>
          <ixx>0.01464</ixx>
          <ixy>0</ixy>
          <ixz>0</ixz>
          <iyy>0.00895</iyy>
          <iyz>-0.00631</iyz>
          <izz>0.00725</izz>
        </inertia>
      </inertial>
      <collision name='motor4_link_collision'>
        <pose frame=''>0 0 0 0 -0 0</pose>
        <geometry>
          <mesh>
            <scale>0.001 0.001 0.001</scale>
            <uri>model://mara_description/meshes/MARA_Link2.stl</uri>
          </mesh>
        </geometry>
        <surface>
          <contact>
            <ode/>
          </contact>
          <friction>
            <ode/>
          </friction>
        </surface>
      </collision>
      <visual name='motor4_link_visual'>
        <pose frame=''>0 0 0 0 -0 0</pose>
        <geometry>
          <mesh>
            <scale>0.001 0.001 0.001</scale>
            <uri>model://mara_description/meshes/MARA_Link2.stl</uri>
          </mesh>
        </geometry>
        <material>
          <script>
            <name>Gazebo/Black</name>
            <uri>file://media/materials/scripts/gazebo.material</uri>
          </script>
        </material>
      </visual>
      <gravity>1</gravity>
      <velocity_decay/>
      <self_collide>1</self_collide>
    </link>
    <joint name='motor4' type='revolute'>
      <child>motor4_link</child>
      <parent>motor3_link</parent>
      <axis>
        <xyz>0 0 1</xyz>
        <limit>
          <lower>-2.3562</lower>
          <upper>2.3562</upper>
          <effort>330</effort>
          <velocity>3.1416</velocity>
        </limit>
        <dynamics>
          <damping>0</damping>
          <friction>0</friction>
          <spring_reference>0</spring_reference>
          <spring_stiffness>0</spring_stiffness>
        </dynamics>
        <use_parent_model_frame>1</use_parent_model_frame>
      </axis>
    </joint>
    <link name='motor5_link'>
      <pose frame=''>8.4e-05 -0.105202 1.40491 0 0 -1.57</pose>
      <inertial>
        <pose frame=''>0 -5e-06 0.03145 0 -0 0</pose>
        <mass>5.8</mass>
        <inertia>
          <ixx>0.06812</ixx>
          <ixy>-4.03897e-28</ixy>
          <ixz>3.30872e-24</ixz>
          <iyy>0.02132</iyy>
          <iyz>0.01978</iyz>
          <izz>0.05126</izz>
        </inertia>
      </inertial>
      <collision name='motor5_link_collision'>
        <pose frame=''>0 0 0 0 -0 0</pose>
        <geometry>
          <mesh>
            <scale>0.001 0.001 0.001</scale>
            <uri>model://mara_description/meshes/MARA_T5.4.stl</uri>
          </mesh>
        </geometry>
        <surface>
          <contact>
            <ode/>
          </contact>
          <friction>
            <ode/>
          </friction>
        </surface>
      </collision>
      <collision name='motor5_link_fixed_joint_lump__motor5_cover_collision_1'>
        <pose frame=''>0 0 0 0 -0 0</pose>
        <geometry>
          <mesh>
            <scale>0.001 0.001 0.001</scale>
            <uri>model://mara_description/meshes/MARA_T5.4_black.stl</uri>
          </mesh>
        </geometry>
        <surface>
          <contact>
            <ode/>
          </contact>
          <friction>
            <ode/>
          </friction>
        </surface>
      </collision>
      <visual name='motor5_link_visual'>
        <pose frame=''>0 0 0 0 -0 0</pose>
        <geometry>
          <mesh>
            <scale>0.001 0.001 0.001</scale>
            <uri>model://mara_description/meshes/MARA_T5.4.stl</uri>
          </mesh>
        </geometry>
        <material>
          <script>
            <name>Gazebo/White</name>
            <uri>file://media/materials/scripts/gazebo.material</uri>
          </script>
        </material>
      </visual>
      <visual name='motor5_link_fixed_joint_lump__motor5_cover_visual_1'>
        <pose frame=''>0 0 0 0 -0 0</pose>
        <geometry>
          <mesh>
            <scale>0.001 0.001 0.001</scale>
            <uri>model://mara_description/meshes/MARA_T5.4_black.stl</uri>
          </mesh>
        </geometry>
        <material>
          <script>
            <name>Gazebo/Black</name>
            <uri>file://media/materials/scripts/gazebo.material</uri>
          </script>
        </material>
      </visual>
      <velocity_decay/>
      <gravity>1</gravity>
      <velocity_decay/>
      <self_collide>1</self_collide>
    </link>
    <joint name='motor5' type='revolute'>
      <child>motor5_link</child>
      <parent>motor4_link</parent>
      <axis>
        <xyz>0.000796 -1 0</xyz>
        <limit>
          <lower>-2.3562</lower>
          <upper>2.3562</upper>
          <effort>330</effort>
          <velocity>3.1416</velocity>
        </limit>
        <dynamics>
          <damping>0</damping>
          <friction>0</friction>
          <spring_reference>0</spring_reference>
          <spring_stiffness>0</spring_stiffness>
        </dynamics>
        <use_parent_model_frame>1</use_parent_model_frame>
      </axis>
    </joint>
    <link name='motor6_link'>
      <pose frame=''>-1e-06 0.001054 1.55167 0 0 -1.57</pose>
      <inertial>
        <pose frame=''>0 -4e-06 0.034826 0 -0 0</pose>
        <mass>3.12652</mass>
        <inertia>
          <ixx>0.00113439</ixx>
          <ixy>1.72996e-08</ixy>
          <ixz>-4.47562e-08</ixz>
          <iyy>0.00115612</iyy>
          <iyz>-4.64078e-08</iyz>
          <izz>0.00043478</izz>
        </inertia>
      </inertial>
      <collision name='motor6_link_collision'>
        <pose frame=''>0 0 0 0 -0 0</pose>
        <geometry>
          <mesh>
            <scale>0.001 0.001 0.001</scale>
            <uri>model://mara_description/meshes/MARA_GripperAdapter.stl</uri>
          </mesh>
        </geometry>
        <surface>
          <contact>
            <ode/>
          </contact>
          <friction>
            <ode/>
          </friction>
        </surface>
      </collision>
      <collision name='motor6_link_fixed_joint_lump__robotiq_arg2f_base_link_collision_1'>
        <pose frame=''>0 0 0.04659 0 -0 3.14</pose>
        <geometry>
          <mesh>
            <scale>0.001 0.001 0.001</scale>
            <uri>model://robotiq_140_gripper_description/meshes/GRIPPER_base_axis.stl</uri>
          </mesh>
        </geometry>
        <surface>
          <contact>
            <ode/>
          </contact>
          <friction>
            <ode/>
          </friction>
        </surface>
      </collision>
      <visual name='motor6_link_visual'>
        <pose frame=''>0 0 0 0 -0 0</pose>
        <geometry>
          <mesh>
            <scale>0.001 0.001 0.001</scale>
            <uri>model://mara_description/meshes/MARA_GripperAdapter.stl</uri>
          </mesh>
        </geometry>
        <material>
          <script>
            <name>Gazebo/Black</name>
            <uri>file://media/materials/scripts/gazebo.material</uri>
          </script>
        </material>
      </visual>
      <visual name='motor6_link_fixed_joint_lump__robotiq_arg2f_base_link_visual_1'>
        <pose frame=''>0 0 0.04659 0 -0 3.14</pose>
        <geometry>
          <mesh>
            <scale>0.001 0.001 0.001</scale>
            <uri>model://robotiq_140_gripper_description/meshes/GRIPPER_base_axis.stl</uri>
          </mesh>
        </geometry>
        <material>
          <script>
            <name>Gazebo/Grey</name>
            <uri>file://media/materials/scripts/gazebo.material</uri>
          </script>
        </material>
      </visual>
      <velocity_decay/>
      <velocity_decay/>
      <gravity>1</gravity>
      <velocity_decay/>
      <self_collide>1</self_collide>
    </link>
    <joint name='motor6' type='revolute'>
      <child>motor6_link</child>
      <parent>motor5_link</parent>
      <axis>
        <xyz>0 0 1</xyz>
        <limit>
          <lower>-2.3562</lower>
          <upper>2.3562</upper>
          <effort>330</effort>
          <velocity>3.1416</velocity>
        </limit>
        <dynamics>
          <damping>0</damping>
          <friction>0</friction>
          <spring_reference>0</spring_reference>
          <spring_stiffness>0</spring_stiffness>
        </dynamics>
        <use_parent_model_frame>1</use_parent_model_frame>
      </axis>
    </joint>
    <link name='left_inner_knuckle'>
      <pose frame=''>-1e-06 -0.011646 1.65968 2.29 -0 0</pose>
      <inertial>
        <pose frame=''>0.000123 0.050785 0.00104 0 -0 0</pose>
        <mass>0.0271177</mass>
        <inertia>
          <ixx>2.6191e-05</ixx>
          <ixy>-2.43617e-07</ixy>
          <ixz>-6.3779e-09</ixz>
          <iyy>2.82702e-06</iyy>
          <iyz>-5.37201e-07</iyz>
          <izz>2.83696e-05</izz>
        </inertia>
      </inertial>
      <visual name='left_inner_knuckle_visual'>
        <pose frame=''>0 0 0 0 -0 0</pose>
        <geometry>
          <mesh>
            <scale>1 1 1</scale>
            <uri>model://robotiq_140_gripper_description/meshes/robotiq_140_left_inner_knuckle.stl</uri>
          </mesh>
        </geometry>
        <material>
          <script>
            <name>Gazebo/Grey</name>
            <uri>file://media/materials/scripts/gazebo.material</uri>
          </script>
        </material>
      </visual>
      <gravity>1</gravity>
      <velocity_decay/>
      <self_collide>1</self_collide>
    </link>
    <joint name='left_inner_knuckle_joint' type='revolute'>
      <child>left_inner_knuckle</child>
      <parent>motor6_link</parent>
      <axis>
        <xyz>-1 0 0</xyz>
        <limit>
          <lower>0</lower>
          <upper>0.87</upper>
          <effort>1000</effort>
          <velocity>2</velocity>
        </limit>
        <dynamics>
          <spring_reference>0</spring_reference>
          <spring_stiffness>0</spring_stiffness>
        </dynamics>
        <use_parent_model_frame>1</use_parent_model_frame>
      </axis>
    </joint>
    <link name='left_outer_knuckle'>
      <pose frame=''>-1e-06 -0.029547 1.65317 2.31 -0 0</pose>
      <inertial>
        <pose frame=''>0 0 0 0 -0 0</pose>
        <mass>0.00853198</mass>
        <inertia>
          <ixx>2.89328e-06</ixx>
          <ixy>0</ixy>
          <ixz>0</ixz>
          <iyy>1.8672e-06</iyy>
          <iyz>-1.21859e-06</iyz>
          <izz>1.21905e-06</izz>
        </inertia>
      </inertial>
      <collision name='left_outer_knuckle_collision'>
        <pose frame=''>0 0 0 0 -0 0</pose>
        <geometry>
          <mesh>
            <scale>1 1 1</scale>
            <uri>model://robotiq_140_gripper_description/meshes/robotiq_140_left_outer_knuckle.stl</uri>
          </mesh>
        </geometry>
        <surface>
          <contact>
            <ode/>
          </contact>
          <friction>
            <ode/>
          </friction>
        </surface>
      </collision>
      <visual name='left_outer_knuckle_visual'>
        <pose frame=''>0 0 0 0 -0 0</pose>
        <geometry>
          <mesh>
            <scale>1 1 1</scale>
            <uri>model://robotiq_140_gripper_description/meshes/robotiq_140_left_outer_knuckle.stl</uri>
          </mesh>
        </geometry>
        <material>
          <script>
            <name>Gazebo/Grey</name>
            <uri>file://media/materials/scripts/gazebo.material</uri>
          </script>
        </material>
      </visual>
      <gravity>1</gravity>
      <velocity_decay/>
      <self_collide>1</self_collide>
    </link>
    <joint name='left_outer_knuckle_joint' type='revolute'>
      <child>left_outer_knuckle</child>
      <parent>motor6_link</parent>
      <axis>
        <xyz>-1 -0 -0</xyz>
        <limit>
          <lower>0</lower>
          <upper>0.875</upper>
          <effort>1000</effort>
          <velocity>2</velocity>
        </limit>
        <dynamics>
          <spring_reference>0</spring_reference>
          <spring_stiffness>0</spring_stiffness>
        </dynamics>
        <use_parent_model_frame>1</use_parent_model_frame>
      </axis>
    </joint>
    <link name='left_outer_finger'>
      <pose frame=''>-1e-06 -0.061038 1.64911 2.31 -0 0</pose>
      <inertial>
        <pose frame=''>0.000301 0.037391 -0.020803 0 -0 0</pose>
        <mass>0.0226142</mass>
        <inertia>
          <ixx>1.52518e-05</ixx>
          <ixy>9.76583e-10</ixy>
          <ixz>-5.43839e-10</ixz>
          <iyy>6.17694e-06</iyy>
          <iyz>6.78636e-06</iyz>
          <izz>1.16495e-05</izz>
        </inertia>
      </inertial>
      <collision name='left_outer_finger_collision'>
        <pose frame=''>0 0 0 0 -0 0</pose>
        <geometry>
          <mesh>
            <scale>1 1 1</scale>
            <uri>model://robotiq_140_gripper_description/meshes/robotiq_140_left_outer_finger.stl</uri>
          </mesh>
        </geometry>
        <surface>
          <contact>
            <ode/>
          </contact>
          <friction>
            <ode/>
          </friction>
        </surface>
      </collision>
      <visual name='left_outer_finger_visual'>
        <pose frame=''>0 0 0 0 -0 0</pose>
        <geometry>
          <mesh>
            <scale>1 1 1</scale>
            <uri>model://robotiq_140_gripper_description/meshes/robotiq_140_left_outer_finger.stl</uri>
          </mesh>
        </geometry>
        <material>
          <script>
            <name>Gazebo/Grey</name>
            <uri>file://media/materials/scripts/gazebo.material</uri>
          </script>
        </material>
      </visual>
      <gravity>1</gravity>
      <velocity_decay/>
      <self_collide>1</self_collide>
    </link>
    <joint name='left_outer_finger_joint' type='revolute'>
      <child>left_outer_finger</child>
      <parent>left_outer_knuckle</parent>
      <axis>
        <xyz>-1 -0 -0</xyz>
        <limit>
          <lower>0.1</lower>
          <upper>0.875</upper>
          <effort>1000</effort>
          <velocity>2</velocity>
        </limit>
        <dynamics>
          <spring_reference>0</spring_reference>
          <spring_stiffness>0</spring_stiffness>
        </dynamics>
        <use_parent_model_frame>1</use_parent_model_frame>
      </axis>
    </joint>
    <link name='left_inner_finger'>
      <pose frame=''>-1e-06 -0.095261 1.72854 1.585 -0 0</pose>
      <inertial>
        <pose frame=''>0 0.031506 -0.017649 0 -0 0</pose>
        <mass>0.0104003</mass>
        <inertia>
          <ixx>6.06863e-06</ixx>
          <ixy>0</ixy>
          <ixz>0</ixz>
          <iyy>7.46305e-07</iyy>
          <iyz>0</iyz>
          <izz>6.21796e-06</izz>
        </inertia>
      </inertial>
      <collision name='left_inner_finger_collision'>
        <pose frame=''>0 0 0 0 -0 0</pose>
        <geometry>
          <mesh>
            <scale>0.001 0.001 0.001</scale>
            <uri>model://robotiq_140_gripper_description/meshes/robotiq_140_left_inner_finger.stl</uri>
          </mesh>
        </geometry>
        <surface>
          <contact>
            <ode/>
          </contact>
          <friction>
            <ode/>
          </friction>
        </surface>
      </collision>
      <visual name='left_inner_finger_visual'>
        <pose frame=''>0 0 0 0 -0 0</pose>
        <geometry>
          <mesh>
            <scale>0.001 0.001 0.001</scale>
            <uri>model://robotiq_140_gripper_description/meshes/robotiq_140_left_inner_finger.stl</uri>
          </mesh>
        </geometry>
        <material>
          <script>
            <name>Gazebo/Grey</name>
            <uri>file://media/materials/scripts/gazebo.material</uri>
          </script>
        </material>
      </visual>
      <gravity>1</gravity>
      <velocity_decay/>
      <self_collide>1</self_collide>
    </link>
    <joint name='left_inner_finger_joint' type='revolute'>
      <child>left_inner_finger</child>
      <parent>left_outer_finger</parent>
      <axis>
        <xyz>1 0 0</xyz>
        <limit>
          <lower>-0.875</lower>
          <upper>0.8757</upper>
          <effort>1000</effort>
          <velocity>2</velocity>
        </limit>
        <dynamics>
          <spring_reference>0</spring_reference>
          <spring_stiffness>0</spring_stiffness>
        </dynamics>
        <use_parent_model_frame>1</use_parent_model_frame>
      </axis>
    </joint>
    <link name='right_inner_knuckle'>
      <pose frame=''>-1e-06 0.013754 1.65968 2.29 -0 3.14159</pose>
      <inertial>
        <pose frame=''>0.000123 0.050785 0.00104 0 -0 0</pose>
        <mass>0.0271177</mass>
        <inertia>
          <ixx>2.6191e-05</ixx>
          <ixy>-2.43617e-07</ixy>
          <ixz>-6.3779e-09</ixz>
          <iyy>2.82702e-06</iyy>
          <iyz>-5.37201e-07</iyz>
          <izz>2.83696e-05</izz>
        </inertia>
      </inertial>
      <visual name='right_inner_knuckle_visual'>
        <pose frame=''>0 0 0 0 -0 0</pose>
        <geometry>
          <mesh>
            <scale>1 1 1</scale>
            <uri>model://robotiq_140_gripper_description/meshes/robotiq_140_right_inner_knuckle.stl</uri>
          </mesh>
        </geometry>
        <material>
          <script>
            <name>Gazebo/Grey</name>
            <uri>file://media/materials/scripts/gazebo.material</uri>
          </script>
        </material>
      </visual>
      <gravity>1</gravity>
      <velocity_decay/>
      <self_collide>1</self_collide>
    </link>
    <joint name='right_inner_knuckle_joint' type='revolute'>
      <child>right_inner_knuckle</child>
      <parent>motor6_link</parent>
      <axis>
        <xyz>1 -0 -0</xyz>
        <limit>
          <lower>0</lower>
          <upper>0.87</upper>
          <effort>1000</effort>
          <velocity>2</velocity>
        </limit>
        <dynamics>
          <spring_reference>0</spring_reference>
          <spring_stiffness>0</spring_stiffness>
        </dynamics>
        <use_parent_model_frame>1</use_parent_model_frame>
      </axis>
    </joint>
    <link name='right_outer_knuckle'>
      <pose frame=''>-1e-06 0.031655 1.65317 2.31 -0 -3.14159</pose>
      <inertial>
        <pose frame=''>0 0 0 0 -0 0</pose>
        <mass>0.00853198</mass>
        <inertia>
          <ixx>2.89328e-06</ixx>
          <ixy>0</ixy>
          <ixz>0</ixz>
          <iyy>1.8672e-06</iyy>
          <iyz>-1.21859e-06</iyz>
          <izz>1.21905e-06</izz>
        </inertia>
      </inertial>
      <collision name='right_outer_knuckle_collision'>
        <pose frame=''>0 0 0 0 -0 0</pose>
        <geometry>
          <mesh>
            <scale>1 1 1</scale>
            <uri>model://robotiq_140_gripper_description/meshes/robotiq_140_right_outer_knuckle.stl</uri>
          </mesh>
        </geometry>
        <surface>
          <contact>
            <ode/>
          </contact>
          <friction>
            <ode/>
          </friction>
        </surface>
      </collision>
      <visual name='right_outer_knuckle_visual'>
        <pose frame=''>0 0 0 0 -0 0</pose>
        <geometry>
          <mesh>
            <scale>1 1 1</scale>
            <uri>model://robotiq_140_gripper_description/meshes/robotiq_140_right_outer_knuckle.stl</uri>
          </mesh>
        </geometry>
        <material>
          <script>
            <name>Gazebo/Grey</name>
            <uri>file://media/materials/scripts/gazebo.material</uri>
          </script>
        </material>
      </visual>
      <gravity>1</gravity>
      <velocity_decay/>
      <self_collide>1</self_collide>
    </link>
    <joint name='right_outer_knuckle_joint' type='revolute'>
      <child>right_outer_knuckle</child>
      <parent>motor6_link</parent>
      <axis>
        <xyz>1 0 -0</xyz>
        <limit>
          <lower>0</lower>
          <upper>0.875</upper>
          <effort>1000</effort>
          <velocity>2</velocity>
        </limit>
        <dynamics>
          <spring_reference>0</spring_reference>
          <spring_stiffness>0</spring_stiffness>
        </dynamics>
        <use_parent_model_frame>1</use_parent_model_frame>
      </axis>
    </joint>
    <link name='right_outer_finger'>
      <pose frame=''>-1e-06 0.063145 1.64911 2.31 -0 -3.14159</pose>
      <inertial>
        <pose frame=''>0.000301 0.037391 -0.020803 0 -0 0</pose>
        <mass>0.0226142</mass>
        <inertia>
          <ixx>1.52518e-05</ixx>
          <ixy>9.76583e-10</ixy>
          <ixz>-5.43839e-10</ixz>
          <iyy>6.17694e-06</iyy>
          <iyz>6.78636e-06</iyz>
          <izz>1.16495e-05</izz>
        </inertia>
      </inertial>
      <collision name='right_outer_finger_collision'>
        <pose frame=''>0 0 0 0 -0 0</pose>
        <geometry>
          <mesh>
            <scale>1 1 1</scale>
            <uri>model://robotiq_140_gripper_description/meshes/robotiq_140_right_outer_finger.stl</uri>
          </mesh>
        </geometry>
        <surface>
          <contact>
            <ode/>
          </contact>
          <friction>
            <ode/>
          </friction>
        </surface>
      </collision>
      <visual name='right_outer_finger_visual'>
        <pose frame=''>0 0 0 0 -0 0</pose>
        <geometry>
          <mesh>
            <scale>1 1 1</scale>
            <uri>model://robotiq_140_gripper_description/meshes/robotiq_140_right_outer_finger.stl</uri>
          </mesh>
        </geometry>
        <material>
          <script>
            <name>Gazebo/Grey</name>
            <uri>file://media/materials/scripts/gazebo.material</uri>
          </script>
        </material>
      </visual>
      <gravity>1</gravity>
      <velocity_decay/>
      <self_collide>1</self_collide>
    </link>
    <joint name='right_outer_finger_joint' type='revolute'>
      <child>right_outer_finger</child>
      <parent>right_outer_knuckle</parent>
      <axis>
        <xyz>1 0 -0</xyz>
        <limit>
          <lower>0.1</lower>
          <upper>0.875</upper>
          <effort>1000</effort>
          <velocity>2</velocity>
        </limit>
        <dynamics>
          <spring_reference>0</spring_reference>
          <spring_stiffness>0</spring_stiffness>
        </dynamics>
        <use_parent_model_frame>1</use_parent_model_frame>
      </axis>
    </joint>
    <link name='right_inner_finger'>
      <pose frame=''>-1e-06 0.097369 1.72854 1.585 -0 -3.14159</pose>
      <inertial>
        <pose frame=''>0 0.031506 -0.017649 0 -0 0</pose>
        <mass>0.0104003</mass>
        <inertia>
          <ixx>6.06863e-06</ixx>
          <ixy>0</ixy>
          <ixz>0</ixz>
          <iyy>7.46305e-07</iyy>
          <iyz>0</iyz>
          <izz>6.21796e-06</izz>
        </inertia>
      </inertial>
      <collision name='right_inner_finger_collision'>
        <pose frame=''>0 0 0 0 -0 0</pose>
        <geometry>
          <mesh>
            <scale>0.001 0.001 0.001</scale>
            <uri>model://robotiq_140_gripper_description/meshes/robotiq_140_right_inner_finger.stl</uri>
          </mesh>
        </geometry>
        <surface>
          <contact>
            <ode/>
          </contact>
          <friction>
            <ode/>
          </friction>
        </surface>
      </collision>
      <visual name='right_inner_finger_visual'>
        <pose frame=''>0 0 0 0 -0 0</pose>
        <geometry>
          <mesh>
            <scale>0.001 0.001 0.001</scale>
            <uri>model://robotiq_140_gripper_description/meshes/robotiq_140_right_inner_finger.stl</uri>
          </mesh>
        </geometry>
        <material>
          <script>
            <name>Gazebo/Grey</name>
            <uri>file://media/materials/scripts/gazebo.material</uri>
          </script>
        </material>
      </visual>
      <gravity>1</gravity>
      <velocity_decay/>
      <self_collide>1</self_collide>
    </link>
    <joint name='right_inner_finger_joint' type='revolute'>
      <child>right_inner_finger</child>
      <parent>right_outer_finger</parent>
      <axis>
        <xyz>-1 -0 0</xyz>
        <limit>
          <lower>-0.875</lower>
          <upper>0.8757</upper>
          <effort>1000</effort>
          <velocity>2</velocity>
        </limit>
        <dynamics>
          <spring_reference>0</spring_reference>
          <spring_stiffness>0</spring_stiffness>
        </dynamics>
        <use_parent_model_frame>1</use_parent_model_frame>
      </axis>
    </joint>
    <plugin name='mara_joint_state' filename='libgazebo_ros_joint_state_publisher.so'>
      <ros>
        <argument>~/out:=joint_states</argument>
      </ros>
      <update_rate>25</update_rate>
      <joint_name>motor1</joint_name>
      <joint_name>motor2</joint_name>
      <joint_name>motor3</joint_name>
      <joint_name>motor4</joint_name>
      <joint_name>motor5</joint_name>
      <joint_name>motor6</joint_name>
      <joint_name>left_inner_knuckle_joint</joint_name>
      <joint_name>left_outer_knuckle_joint</joint_name>
      <joint_name>left_outer_finger_joint</joint_name>
      <joint_name>left_inner_finger_joint</joint_name>
      <joint_name>right_inner_knuckle_joint</joint_name>
      <joint_name>right_outer_knuckle_joint</joint_name>
      <joint_name>right_outer_finger_joint</joint_name>
      <joint_name>right_inner_finger_joint</joint_name>
    </plugin>
    <plugin name='hros_actuation_servomotor_000000000001' filename='libmara_gazebo_joint_plugin.so'>
      <ros/>
      <axis1>motor2</axis1>
      <axis2>motor1</axis2>
      <type>series14</type>
    </plugin>
    <plugin name='hros_actuation_servomotor_000000000002' filename='libmara_gazebo_joint_plugin.so'>
      <ros/>
      <axis1>motor3</axis1>
      <axis2>motor4</axis2>
      <type>series17</type>
    </plugin>
    <plugin name='hros_actuation_servomotor_000000000003' filename='libmara_gazebo_joint_plugin.so'>
      <ros/>
      <axis1>motor5</axis1>
      <axis2>motor6</axis2>
      <type>series20</type>
    </plugin>
    <static>0</static>
    <joint name='left_inner_finger_knuckle_joint' type='revolute'>
      <pose frame=''>0 0.006 -0.018 0 -0 0</pose>
      <parent>mara::left_inner_knuckle</parent>
      <child>mara::left_inner_finger</child>
      <axis>
        <xyz>1 0 0</xyz>
        <limit>
          <lower>-0.8</lower>
          <upper>0.8</upper>
          <velocity>2</velocity>
          <effort>1000</effort>
        </limit>
        <use_parent_model_frame>1</use_parent_model_frame>
      </axis>
    </joint>
    <joint name='right_inner_finger_knuckle_joint' type='revolute'>
      <pose frame=''>0 0.006 -0.018 0 -0 0</pose>
      <parent>mara::right_inner_knuckle</parent>
      <child>mara::right_inner_finger</child>
      <axis>
        <xyz>-1 0 0</xyz>
        <limit>
          <lower>-0.8</lower>
          <upper>0.8</upper>
          <velocity>2</velocity>
          <effort>1000</effort>
        </limit>
        <use_parent_model_frame>1</use_parent_model_frame>
      </axis>
    </joint>
    <plugin name='hros_actuation_gripper_000000000004' filename='librobotiq_140_gripper_gazebo_plugin.so'/>
  </model>
</sdf>
